Workbook

Sheet Guide
B1: APD Project Tracker
B2: A single-file, OneDrive/SharePoint-hosted version of the APD Project Management Dashboard (without the AI features).
B4: Getting started
B5: 1. Add a project | C5: Go to Projects and type the project name in the first empty row (column A). Everything else on that row is optional; grey columns calculate themselves.
B6: 2. Log records | C6: On any register sheet, pick the Project from the dropdown in column A and fill in the row. Dropdowns, date and number checks are built in.
B7: 3. View results | C7: Dashboard shows the portfolio, alerts and upcoming work. Project Summary (pick a project in C3) is a printable one-page report. Gantt draws the selected project's milestones. Charts shows the trends.
B8: 4. Example rows | C8: This is the blank copy: every sheet is empty and ready for your data.
B10: Colour key
B11: Blue text | C11: Input cells - type here.
B12: Grey cells / grey headers | C12: Formulas - do not overwrite (Project Health, budgets, buckets, flags, ranks).
B13: Yellow | C13: Selector cells (Project Summary C3, Search B3).
B14: Green / Amber / Red | C14: Health ratings. Schedule and Budget: green below 95%, amber 95-115%, red above 115% (same rules as the web app). Risk: red if any open Critical risk, amber if any High.
B16: How the numbers work (same rules as the web tool)
B17: Effective budget | C17: Latest Approved Budget if entered, otherwise Original Budget plus approved Variations.
B18: Forecast at completion | C18: For each project and month, an Actual replaces that month's Forecast - they are never added together. Enter one line per project, month and type.
B19: Revised completion | C19: Target Completion plus days from approved EOT Claims (Days Granted, or Days Claimed if none recorded).
B20: Overdue project | C20: Target Completion has passed and the status is not Project Completion, Defects Liability, Complete or Cancelled.
B21: Risk score | C21: Likelihood (1-5) x Consequence (1-5): 16+ Critical, 10-15 High, 5-9 Medium, below 5 Low.
B23: Limits (fixed row capacity - extend by copying the last formula row down)
B24: Projects | C24: 100
B25: Tasks | C25: 1,000
B26: Cash Flow | C26: 2,000
B27: Every other register | C27: 500 rows each
B28: Dashboard portfolio table | C28: Shows the first 30 projects; the Projects sheet always shows all.
B30: Macros (optional - see the VBA folder)
B31: What they add | C31: Global search across every sheet, an automatic Activity Log (who changed what, when), recurring tasks (marking a recurring task Done creates the next one), one-click PDF of the Project Summary, a dated backup copy, and an Outlook email digest of overdue / expiring items.
B32: Without macros | C32: Everything above that is a formula still works - dashboard, health, alerts, summary, Gantt, charts, dropdowns. Use Ctrl+F (Within: Workbook) for search.
B34: Keeping the data in your company's OneDrive / SharePoint
B35: Where to save | C35: Save this file in a OneDrive for Business or SharePoint document library your IT department approves. The data then lives in the company tenant under its retention, backup and access policies.
B36: Access control | C36: Use the library's sharing settings: Edit for the project team, View for read-only stakeholders. Excel Version History restores earlier versions.
B37: Co-authoring | C37: Several people can edit the same .xlsx at once in Excel desktop or the browser. Avoid sorting a register while others are editing it.
B38: What is not in a spreadsheet | C38: Per-user logins and per-project permissions, file attachments, site photo upload/map, scheduled emails and the AI assistant. Link to files in SharePoint (link columns on Documents, Meeting Minutes and Site Visits) instead.
B40: Sheet index
B41: Dashboard | C41: Portfolio table, alerts, today & upcoming, top risks.
B42: Project Summary | C42: One-page report for the selected project.
B43: Gantt | C43: Weekly bar chart of the selected project's milestones.
B44: Charts | C44: Status, budget vs forecast, S-curve, risk bands.
B45: Search | C45: Cross-sheet search (needs the macros).
B46: Projects | C46: One row per project. Grey columns are formulas - do not type in them.
B47: Tasks | C47: Register - one row per record.
...

Sheet Dashboard
A1: APD Project Management Dashboard | F1: As at | G1: =TODAY() -> 46306
A2: Every figure here is a live formula over the register sheets.
A4: Total Projects | C4: In Construction | E4: Overdue Projects | G4: Total Approved Budget
A5: =COUNTA(Projects!$A$2:$A$101) -> 0 | C5: =COUNTIF(Projects!$D$2:$D$101,"Construction") -> 0 | E5: =COUNTIF(Projects!$X$2:$X$101,"Overdue") -> 0 | G5: =SUM(Projects!$R$2:$R$101) -> 0
A7: Portfolio (first 30 projects - full list on the Projects sheet)
A8: Project | B8: Status | C8: Project Manager | D8: Revised Completion | E8: Effective Budget | F8: Forecast at Completion | G8: Budget Variance | H8: Schedule | I8: Budget | J8: Risk | K8: Overall | L8: Open Tasks | M8: Open Actions | N8: Open RFIs | O8: Open Defects
A9: =IF(INDEX(Projects!$A$2:$A$101,ROWS(A$9:A9))="","",INDEX(Projects!$A$2:$A$101,ROWS(A$9:A9))) | B9: =IF($A9="","",IFERROR(IF(INDEX(Projects!$D$2:$D$101,MATCH($A9,Projects!$A$2:$A$101,0))="","",INDEX(Projects!$D$2:$D$101,MATCH($A9,Projects!$A$2:$A$101,0))),"")) | C9: =IF($A9="","",IFERROR(IF(INDEX(Projects!$F$2:$F$101,MATCH($A9,Projects!$A$2:$A$101,0))="","",INDEX(Projects!$F$2:$F$101,MATCH($A9,Projects!$A$2:$A$101,0))),"")) | D9: =IF($A9="","",IFERROR(IF(INDEX(Projects!$W$2:$W$101,MATCH($A9,Projects!$A$2:$A$101,0))="","",INDEX(Projects!$W$2:$W$101,MATCH($A9,Projects!$A$2:$A$101,0))),"")) | E9: =IF($A9="","",IFERROR(IF(INDEX(Projects!$R$2:$R$101,MATCH($A9,Projects!$A$2:$A$101,0))="","",INDEX(Projects!$R$2:$R$101,MATCH($A9,Projects!$A$2:$A$101,0))),"")) | F9: =IF($A9="","",IFERROR(IF(INDEX(Projects!$T$2:$T$101,MATCH($A9,Projects!$A$2:$A$101,0))="","",INDEX(Projects!$T$2:$T$101,MATCH($A9,Projects!$A$2:$A$101,0))),"")) | G9: =IF($A9="","",IFERROR(IF(INDEX(Projects!$U$2:$U$101,MATCH($A9,Projects!$A$2:$A$101,0))="","",INDEX(Projects!$U$2:$U$101,MATCH($A9,Projects!$A$2:$A$101,0))),"")) | H9: =IF($A9="","",IFERROR(IF(INDEX(Projects!$Z$2:$Z$101,MATCH($A9,Projects!$A$2:$A$101,0))="","",INDEX(Projects!$Z$2:$Z$101,MATCH($A9,Projects!$A$2:$A$101,0))),"")) | I9: =IF($A9="","",IFERROR(IF(INDEX(Projects!$AB$2:$AB$101,MATCH($A9,Projects!$A$2:$A$101,0))="","",INDEX(Projects!$AB$2:$AB$101,MATCH($A9,Projects!$A$2:$A$101,0))),"")) | J9: =IF($A9="","",IFERROR(IF(INDEX(Projects!$AE$2:$AE$101,MATCH($A9,Projects!$A$2:$A$101,0))="","",INDEX(Projects!$AE$2:$AE$101,MATCH($A9,Projects!$A$2:$A$101,0))),"")) | K9: =IF($A9="","",IFERROR(IF(INDEX(Projects!$AF$2:$AF$101,MATCH($A9,Projects!$A$2:$A$101,0))="","",INDEX(Projects!$AF$2:$AF$101,MATCH($A9,Projects!$A$2:$A$101,0))),"")) | L9: =IF($A9="","",IFERROR(IF(INDEX(Projects!$AG$2:$AG$101,MATCH($A9,Projects!$A$2:$A$101,0))="","",INDEX(Projects!$AG$2:$AG$101,MATCH($A9,Projects!$A$2:$A$101,0))),"")) | M9: =IF($A9="","",IFERROR(IF(INDEX(Projects!$AH$2:$AH$101,MATCH($A9,Projects!$A$2:$A$101,0))="","",INDEX(Projects!$AH$2:$AH$101,MATCH($A9,Projects!$A$2:$A$101,0))),"")) | N9: =IF($A9="","",IFERROR(IF(INDEX(Projects!$AI$2:$AI$101,MATCH($A9,Projects!$A$2:$A$101,0))="","",INDEX(Projects!$AI$2:$AI$101,MATCH($A9,Projects!$A$2:$A$101,0))),"")) | O9: =IF($A9="","",IFERROR(IF(INDEX(Projects!$AJ$2:$AJ$101,MATCH($A9,Projects!$A$2:$A$101,0))="","",INDEX(Projects!$AJ$2:$AJ$101,MATCH($A9,Projects!$A$2:$A$101,0))),""))
A10: =IF(INDEX(Projects!$A$2:$A$101,ROWS(A$9:A10))="","",INDEX(Projects!$A$2:$A$101,ROWS(A$9:A10))) | B10: =IF($A10="","",IFERROR(IF(INDEX(Projects!$D$2:$D$101,MATCH($A10,Projects!$A$2:$A$101,0))="","",INDEX(Projects!$D$2:$D$101,MATCH($A10,Projects!$A$2:$A$101,0))),"")) | C10: =IF($A10="","",IFERROR(IF(INDEX(Projects!$F$2:$F$101,MATCH($A10,Projects!$A$2:$A$101,0))="","",INDEX(Projects!$F$2:$F$101,MATCH($A10,Projects!$A$2:$A$101,0))),"")) | D10: =IF($A10="","",IFERROR(IF(INDEX(Projects!$W$2:$W$101,MATCH($A10,Projects!$A$2:$A$101,0))="","",INDEX(Projects!$W$2:$W$101,MATCH($A10,Projects!$A$2:$A$101,0))),"")) | E10: =IF($A10="","",IFERROR(IF(INDEX(Projects!$R$2:$R$101,MATCH($A10,Projects!$A$2:$A$101,0))="","",INDEX(Projects!$R$2:$R$101,MATCH($A10,Projects!$A$2:$A$101,0))),"")) | F10: =IF($A10="","",IFERROR(IF(INDEX(Projects!$T$2:$T$101,MATCH($A10,Projects!$A$2:$A$101,0))="","",INDEX(Projects!$T$2:$T$101,MATCH($A10,Projects!$A$2:$A$101,0))),"")) | G10: =IF($A10="","",IFERROR(IF(INDEX(Projects!$U$2:$U$101,MATCH($A10,Projects!$A$2:$A$101,0))="","",INDEX(Projects!$U$2:$U$101,MATCH($A10,Projects!$A$2:$A$101,0))),"")) | H10: =IF($A10="","",IFERROR(IF(INDEX(Projects!$Z$2:$Z$101,MATCH($A10,Projects!$A$2:$A$101,0))="","",INDEX(Projects!$Z$2:$Z$101,MATCH($A10,Projects!$A$2:$A$101,0))),"")) | I10: =IF($A10="","",IFERROR(IF(INDEX(Projects!$AB$2:$AB$101,MATCH($A10,Projects!$A$2:$A$101,0))="","",INDEX(Projects!$AB$2:$AB$101,MATCH($A10,Projects!$A$2:$A$101,0))),"")) | J10: =IF($A10="","",IFERROR(IF(INDEX(Projects!$AE$2:$AE$101,MATCH($A10,Projects!$A$2:$A$101,0))="","",INDEX(Projects!$AE$2:$AE$101,MATCH($A10,Projects!$A$2:$A$101,0))),"")) | K10: =IF($A10="","",IFERROR(IF(INDEX(Projects!$AF$2:$AF$101,MATCH($A10,Projects!$A$2:$A$101,0))="","",INDEX(Projects!$AF$2:$AF$101,MATCH($A10,Projects!$A$2:$A$101,0))),"")) | L10: =IF($A10="","",IFERROR(IF(INDEX(Projects!$AG$2:$AG$101,MATCH($A10,Projects!$A$2:$A$101,0))="","",INDEX(Projects!$AG$2:$AG$101,MATCH($A10,Projects!$A$2:$A$101,0))),"")) | M10: =IF($A10="","",IFERROR(IF(INDEX(Projects!$AH$2:$AH$101,MATCH($A10,Projects!$A$2:$A$101,0))="","",INDEX(Projects!$AH$2:$AH$101,MATCH($A10,Projects!$A$2:$A$101,0))),"")) | N10: =IF($A10="","",IFERROR(IF(INDEX(Projects!$AI$2:$AI$101,MATCH($A10,Projects!$A$2:$A$101,0))="","",INDEX(Projects!$AI$2:$AI$101,MATCH($A10,Projects!$A$2:$A$101,0))),"")) | O10: =IF($A10="","",IFERROR(IF(INDEX(Projects!$AJ$2:$AJ$101,MATCH($A10,Projects!$A$2:$A$101,0))="","",INDEX(Projects!$AJ$2:$AJ$101,MATCH($A10,Projects!$A$2:$A$101,0))),""))
A11: =IF(INDEX(Projects!$A$2:$A$101,ROWS(A$9:A11))="","",INDEX(Projects!$A$2:$A$101,ROWS(A$9:A11))) | B11: =IF($A11="","",IFERROR(IF(INDEX(Projects!$D$2:$D$101,MATCH($A11,Projects!$A$2:$A$101,0))="","",INDEX(Projects!$D$2:$D$101,MATCH($A11,Projects!$A$2:$A$101,0))),"")) | C11: =IF($A11="","",IFERROR(IF(INDEX(Projects!$F$2:$F$101,MATCH($A11,Projects!$A$2:$A$101,0))="","",INDEX(Projects!$F$2:$F$101,MATCH($A11,Projects!$A$2:$A$101,0))),"")) | D11: =IF($A11="","",IFERROR(IF(INDEX(Projects!$W$2:$W$101,MATCH($A11,Projects!$A$2:$A$101,0))="","",INDEX(Projects!$W$2:$W$101,MATCH($A11,Projects!$A$2:$A$101,0))),"")) | E11: =IF($A11="","",IFERROR(IF(INDEX(Projects!$R$2:$R$101,MATCH($A11,Projects!$A$2:$A$101,0))="","",INDEX(Projects!$R$2:$R$101,MATCH($A11,Projects!$A$2:$A$101,0))),"")) | F11: =IF($A11="","",IFERROR(IF(INDEX(Projects!$T$2:$T$101,MATCH($A11,Projects!$A$2:$A$101,0))="","",INDEX(Projects!$T$2:$T$101,MATCH($A11,Projects!$A$2:$A$101,0))),"")) | G11: =IF($A11="","",IFERROR(IF(INDEX(Projects!$U$2:$U$101,MATCH($A11,Projects!$A$2:$A$101,0))="","",INDEX(Projects!$U$2:$U$101,MATCH($A11,Projects!$A$2:$A$101,0))),"")) | H11: =IF($A11="","",IFERROR(IF(INDEX(Projects!$Z$2:$Z$101,MATCH($A11,Projects!$A$2:$A$101,0))="","",INDEX(Projects!$Z$2:$Z$101,MATCH($A11,Projects!$A$2:$A$101,0))),"")) | I11: =IF($A11="","",IFERROR(IF(INDEX(Projects!$AB$2:$AB$101,MATCH($A11,Projects!$A$2:$A$101,0))="","",INDEX(Projects!$AB$2:$AB$101,MATCH($A11,Projects!$A$2:$A$101,0))),"")) | J11: =IF($A11="","",IFERROR(IF(INDEX(Projects!$AE$2:$AE$101,MATCH($A11,Projects!$A$2:$A$101,0))="","",INDEX(Projects!$AE$2:$AE$101,MATCH($A11,Projects!$A$2:$A$101,0))),"")) | K11: =IF($A11="","",IFERROR(IF(INDEX(Projects!$AF$2:$AF$101,MATCH($A11,Projects!$A$2:$A$101,0))="","",INDEX(Projects!$AF$2:$AF$101,MATCH($A11,Projects!$A$2:$A$101,0))),"")) | L11: =IF($A11="","",IFERROR(IF(INDEX(Projects!$AG$2:$AG$101,MATCH($A11,Projects!$A$2:$A$101,0))="","",INDEX(Projects!$AG$2:$AG$101,MATCH($A11,Projects!$A$2:$A$101,0))),"")) | M11: =IF($A11="","",IFERROR(IF(INDEX(Projects!$AH$2:$AH$101,MATCH($A11,Projects!$A$2:$A$101,0))="","",INDEX(Projects!$AH$2:$AH$101,MATCH($A11,Projects!$A$2:$A$101,0))),"")) | N11: =IF($A11="","",IFERROR(IF(INDEX(Projects!$AI$2:$AI$101,MATCH($A11,Projects!$A$2:$A$101,0))="","",INDEX(Projects!$AI$2:$AI$101,MATCH($A11,Projects!$A$2:$A$101,0))),"")) | O11: =IF($A11="","",IFERROR(IF(INDEX(Projects!$AJ$2:$AJ$101,MATCH($A11,Projects!$A$2:$A$101,0))="","",INDEX(Projects!$AJ$2:$AJ$101,MATCH($A11,Projects!$A$2:$A$101,0))),""))
A12: =IF(INDEX(Projects!$A$2:$A$101,ROWS(A$9:A12))="","",INDEX(Projects!$A$2:$A$101,ROWS(A$9:A12))) | B12: =IF($A12="","",IFERROR(IF(INDEX(Projects!$D$2:$D$101,MATCH($A12,Projects!$A$2:$A$101,0))="","",INDEX(Projects!$D$2:$D$101,MATCH($A12,Projects!$A$2:$A$101,0))),"")) | C12: =IF($A12="","",IFERROR(IF(INDEX(Projects!$F$2:$F$101,MATCH($A12,Projects!$A$2:$A$101,0))="","",INDEX(Projects!$F$2:$F$101,MATCH($A12,Projects!$A$2:$A$101,0))),"")) | D12: =IF($A12="","",IFERROR(IF(INDEX(Projects!$W$2:$W$101,MATCH($A12,Projects!$A$2:$A$101,0))="","",INDEX(Projects!$W$2:$W$101,MATCH($A12,Projects!$A$2:$A$101,0))),"")) | E12: =IF($A12="","",IFERROR(IF(INDEX(Projects!$R$2:$R$101,MATCH($A12,Projects!$A$2:$A$101,0))="","",INDEX(Projects!$R$2:$R$101,MATCH($A12,Projects!$A$2:$A$101,0))),"")) | F12: =IF($A12="","",IFERROR(IF(INDEX(Projects!$T$2:$T$101,MATCH($A12,Projects!$A$2:$A$101,0))="","",INDEX(Projects!$T$2:$T$101,MATCH($A12,Projects!$A$2:$A$101,0))),"")) | G12: =IF($A12="","",IFERROR(IF(INDEX(Projects!$U$2:$U$101,MATCH($A12,Projects!$A$2:$A$101,0))="","",INDEX(Projects!$U$2:$U$101,MATCH($A12,Projects!$A$2:$A$101,0))),"")) | H12: =IF($A12="","",IFERROR(IF(INDEX(Projects!$Z$2:$Z$101,MATCH($A12,Projects!$A$2:$A$101,0))="","",INDEX(Projects!$Z$2:$Z$101,MATCH($A12,Projects!$A$2:$A$101,0))),"")) | I12: =IF($A12="","",IFERROR(IF(INDEX(Projects!$AB$2:$AB$101,MATCH($A12,Projects!$A$2:$A$101,0))="","",INDEX(Projects!$AB$2:$AB$101,MATCH($A12,Projects!$A$2:$A$101,0))),"")) | J12: =IF($A12="","",IFERROR(IF(INDEX(Projects!$AE$2:$AE$101,MATCH($A12,Projects!$A$2:$A$101,0))="","",INDEX(Projects!$AE$2:$AE$101,MATCH($A12,Projects!$A$2:$A$101,0))),"")) | K12: =IF($A12="","",IFERROR(IF(INDEX(Projects!$AF$2:$AF$101,MATCH($A12,Projects!$A$2:$A$101,0))="","",INDEX(Projects!$AF$2:$AF$101,MATCH($A12,Projects!$A$2:$A$101,0))),"")) | L12: =IF($A12="","",IFERROR(IF(INDEX(Projects!$AG$2:$AG$101,MATCH($A12,Projects!$A$2:$A$101,0))="","",INDEX(Projects!$AG$2:$AG$101,MATCH($A12,Projects!$A$2:$A$101,0))),"")) | M12: =IF($A12="","",IFERROR(IF(INDEX(Projects!$AH$2:$AH$101,MATCH($A12,Projects!$A$2:$A$101,0))="","",INDEX(Projects!$AH$2:$AH$101,MATCH($A12,Projects!$A$2:$A$101,0))),"")) | N12: =IF($A12="","",IFERROR(IF(INDEX(Projects!$AI$2:$AI$101,MATCH($A12,Projects!$A$2:$A$101,0))="","",INDEX(Projects!$AI$2:$AI$101,MATCH($A12,Projects!$A$2:$A$101,0))),"")) | O12: =IF($A12="","",IFERROR(IF(INDEX(Projects!$AJ$2:$AJ$101,MATCH($A12,Projects!$A$2:$A$101,0))="","",INDEX(Projects!$AJ$2:$AJ$101,MATCH($A12,Projects!$A$2:$A$101,0))),""))
A13: =IF(INDEX(Projects!$A$2:$A$101,ROWS(A$9:A13))="","",INDEX(Projects!$A$2:$A$101,ROWS(A$9:A13))) | B13: =IF($A13="","",IFERROR(IF(INDEX(Projects!$D$2:$D$101,MATCH($A13,Projects!$A$2:$A$101,0))="","",INDEX(Projects!$D$2:$D$101,MATCH($A13,Projects!$A$2:$A$101,0))),"")) | C13: =IF($A13="","",IFERROR(IF(INDEX(Projects!$F$2:$F$101,MATCH($A13,Projects!$A$2:$A$101,0))="","",INDEX(Projects!$F$2:$F$101,MATCH($A13,Projects!$A$2:$A$101,0))),"")) | D13: =IF($A13="","",IFERROR(IF(INDEX(Projects!$W$2:$W$101,MATCH($A13,Projects!$A$2:$A$101,0))="","",INDEX(Projects!$W$2:$W$101,MATCH($A13,Projects!$A$2:$A$101,0))),"")) | E13: =IF($A13="","",IFERROR(IF(INDEX(Projects!$R$2:$R$101,MATCH($A13,Projects!$A$2:$A$101,0))="","",INDEX(Projects!$R$2:$R$101,MATCH($A13,Projects!$A$2:$A$101,0))),"")) | F13: =IF($A13="","",IFERROR(IF(INDEX(Projects!$T$2:$T$101,MATCH($A13,Projects!$A$2:$A$101,0))="","",INDEX(Projects!$T$2:$T$101,MATCH($A13,Projects!$A$2:$A$101,0))),"")) | G13: =IF($A13="","",IFERROR(IF(INDEX(Projects!$U$2:$U$101,MATCH($A13,Projects!$A$2:$A$101,0))="","",INDEX(Projects!$U$2:$U$101,MATCH($A13,Projects!$A$2:$A$101,0))),"")) | H13: =IF($A13="","",IFERROR(IF(INDEX(Projects!$Z$2:$Z$101,MATCH($A13,Projects!$A$2:$A$101,0))="","",INDEX(Projects!$Z$2:$Z$101,MATCH($A13,Projects!$A$2:$A$101,0))),"")) | I13: =IF($A13="","",IFERROR(IF(INDEX(Projects!$AB$2:$AB$101,MATCH($A13,Projects!$A$2:$A$101,0))="","",INDEX(Projects!$AB$2:$AB$101,MATCH($A13,Projects!$A$2:$A$101,0))),"")) | J13: =IF($A13="","",IFERROR(IF(INDEX(Projects!$AE$2:$AE$101,MATCH($A13,Projects!$A$2:$A$101,0))="","",INDEX(Projects!$AE$2:$AE$101,MATCH($A13,Projects!$A$2:$A$101,0))),"")) | K13: =IF($A13="","",IFERROR(IF(INDEX(Projects!$AF$2:$AF$101,MATCH($A13,Projects!$A$2:$A$101,0))="","",INDEX(Projects!$AF$2:$AF$101,MATCH($A13,Projects!$A$2:$A$101,0))),"")) | L13: =IF($A13="","",IFERROR(IF(INDEX(Projects!$AG$2:$AG$101,MATCH($A13,Projects!$A$2:$A$101,0))="","",INDEX(Projects!$AG$2:$AG$101,MATCH($A13,Projects!$A$2:$A$101,0))),"")) | M13: =IF($A13="","",IFERROR(IF(INDEX(Projects!$AH$2:$AH$101,MATCH($A13,Projects!$A$2:$A$101,0))="","",INDEX(Projects!$AH$2:$AH$101,MATCH($A13,Projects!$A$2:$A$101,0))),"")) | N13: =IF($A13="","",IFERROR(IF(INDEX(Projects!$AI$2:$AI$101,MATCH($A13,Projects!$A$2:$A$101,0))="","",INDEX(Projects!$AI$2:$AI$101,MATCH($A13,Projects!$A$2:$A$101,0))),"")) | O13: =IF($A13="","",IFERROR(IF(INDEX(Projects!$AJ$2:$AJ$101,MATCH($A13,Projects!$A$2:$A$101,0))="","",INDEX(Projects!$AJ$2:$AJ$101,MATCH($A13,Projects!$A$2:$A$101,0))),""))
A14: =IF(INDEX(Projects!$A$2:$A$101,ROWS(A$9:A14))="","",INDEX(Projects!$A$2:$A$101,ROWS(A$9:A14))) | B14: =IF($A14="","",IFERROR(IF(INDEX(Projects!$D$2:$D$101,MATCH($A14,Projects!$A$2:$A$101,0))="","",INDEX(Projects!$D$2:$D$101,MATCH($A14,Projects!$A$2:$A$101,0))),"")) | C14: =IF($A14="","",IFERROR(IF(INDEX(Projects!$F$2:$F$101,MATCH($A14,Projects!$A$2:$A$101,0))="","",INDEX(Projects!$F$2:$F$101,MATCH($A14,Projects!$A$2:$A$101,0))),"")) | D14: =IF($A14="","",IFERROR(IF(INDEX(Projects!$W$2:$W$101,MATCH($A14,Projects!$A$2:$A$101,0))="","",INDEX(Projects!$W$2:$W$101,MATCH($A14,Projects!$A$2:$A$101,0))),"")) | E14: =IF($A14="","",IFERROR(IF(INDEX(Projects!$R$2:$R$101,MATCH($A14,Projects!$A$2:$A$101,0))="","",INDEX(Projects!$R$2:$R$101,MATCH($A14,Projects!$A$2:$A$101,0))),"")) | F14: =IF($A14="","",IFERROR(IF(INDEX(Projects!$T$2:$T$101,MATCH($A14,Projects!$A$2:$A$101,0))="","",INDEX(Projects!$T$2:$T$101,MATCH($A14,Projects!$A$2:$A$101,0))),"")) | G14: =IF($A14="","",IFERROR(IF(INDEX(Projects!$U$2:$U$101,MATCH($A14,Projects!$A$2:$A$101,0))="","",INDEX(Projects!$U$2:$U$101,MATCH($A14,Projects!$A$2:$A$101,0))),"")) | H14: =IF($A14="","",IFERROR(IF(INDEX(Projects!$Z$2:$Z$101,MATCH($A14,Projects!$A$2:$A$101,0))="","",INDEX(Projects!$Z$2:$Z$101,MATCH($A14,Projects!$A$2:$A$101,0))),"")) | I14: =IF($A14="","",IFERROR(IF(INDEX(Projects!$AB$2:$AB$101,MATCH($A14,Projects!$A$2:$A$101,0))="","",INDEX(Projects!$AB$2:$AB$101,MATCH($A14,Projects!$A$2:$A$101,0))),"")) | J14: =IF($A14="","",IFERROR(IF(INDEX(Projects!$AE$2:$AE$101,MATCH($A14,Projects!$A$2:$A$101,0))="","",INDEX(Projects!$AE$2:$AE$101,MATCH($A14,Projects!$A$2:$A$101,0))),"")) | K14: =IF($A14="","",IFERROR(IF(INDEX(Projects!$AF$2:$AF$101,MATCH($A14,Projects!$A$2:$A$101,0))="","",INDEX(Projects!$AF$2:$AF$101,MATCH($A14,Projects!$A$2:$A$101,0))),"")) | L14: =IF($A14="","",IFERROR(IF(INDEX(Projects!$AG$2:$AG$101,MATCH($A14,Projects!$A$2:$A$101,0))="","",INDEX(Projects!$AG$2:$AG$101,MATCH($A14,Projects!$A$2:$A$101,0))),"")) | M14: =IF($A14="","",IFERROR(IF(INDEX(Projects!$AH$2:$AH$101,MATCH($A14,Projects!$A$2:$A$101,0))="","",INDEX(Projects!$AH$2:$AH$101,MATCH($A14,Projects!$A$2:$A$101,0))),"")) | N14: =IF($A14="","",IFERROR(IF(INDEX(Projects!$AI$2:$AI$101,MATCH($A14,Projects!$A$2:$A$101,0))="","",INDEX(Projects!$AI$2:$AI$101,MATCH($A14,Projects!$A$2:$A$101,0))),"")) | O14: =IF($A14="","",IFERROR(IF(INDEX(Projects!$AJ$2:$AJ$101,MATCH($A14,Projects!$A$2:$A$101,0))="","",INDEX(Projects!$AJ$2:$AJ$101,MATCH($A14,Projects!$A$2:$A$101,0))),""))
A15: =IF(INDEX(Projects!$A$2:$A$101,ROWS(A$9:A15))="","",INDEX(Projects!$A$2:$A$101,ROWS(A$9:A15))) | B15: =IF($A15="","",IFERROR(IF(INDEX(Projects!$D$2:$D$101,MATCH($A15,Projects!$A$2:$A$101,0))="","",INDEX(Projects!$D$2:$D$101,MATCH($A15,Projects!$A$2:$A$101,0))),"")) | C15: =IF($A15="","",IFERROR(IF(INDEX(Projects!$F$2:$F$101,MATCH($A15,Projects!$A$2:$A$101,0))="","",INDEX(Projects!$F$2:$F$101,MATCH($A15,Projects!$A$2:$A$101,0))),"")) | D15: =IF($A15="","",IFERROR(IF(INDEX(Projects!$W$2:$W$101,MATCH($A15,Projects!$A$2:$A$101,0))="","",INDEX(Projects!$W$2:$W$101,MATCH($A15,Projects!$A$2:$A$101,0))),"")) | E15: =IF($A15="","",IFERROR(IF(INDEX(Projects!$R$2:$R$101,MATCH($A15,Projects!$A$2:$A$101,0))="","",INDEX(Projects!$R$2:$R$101,MATCH($A15,Projects!$A$2:$A$101,0))),"")) | F15: =IF($A15="","",IFERROR(IF(INDEX(Projects!$T$2:$T$101,MATCH($A15,Projects!$A$2:$A$101,0))="","",INDEX(Projects!$T$2:$T$101,MATCH($A15,Projects!$A$2:$A$101,0))),"")) | G15: =IF($A15="","",IFERROR(IF(INDEX(Projects!$U$2:$U$101,MATCH($A15,Projects!$A$2:$A$101,0))="","",INDEX(Projects!$U$2:$U$101,MATCH($A15,Projects!$A$2:$A$101,0))),"")) | H15: =IF($A15="","",IFERROR(IF(INDEX(Projects!$Z$2:$Z$101,MATCH($A15,Projects!$A$2:$A$101,0))="","",INDEX(Projects!$Z$2:$Z$101,MATCH($A15,Projects!$A$2:$A$101,0))),"")) | I15: =IF($A15="","",IFERROR(IF(INDEX(Projects!$AB$2:$AB$101,MATCH($A15,Projects!$A$2:$A$101,0))="","",INDEX(Projects!$AB$2:$AB$101,MATCH($A15,Projects!$A$2:$A$101,0))),"")) | J15: =IF($A15="","",IFERROR(IF(INDEX(Projects!$AE$2:$AE$101,MATCH($A15,Projects!$A$2:$A$101,0))="","",INDEX(Projects!$AE$2:$AE$101,MATCH($A15,Projects!$A$2:$A$101,0))),"")) | K15: =IF($A15="","",IFERROR(IF(INDEX(Projects!$AF$2:$AF$101,MATCH($A15,Projects!$A$2:$A$101,0))="","",INDEX(Projects!$AF$2:$AF$101,MATCH($A15,Projects!$A$2:$A$101,0))),"")) | L15: =IF($A15="","",IFERROR(IF(INDEX(Projects!$AG$2:$AG$101,MATCH($A15,Projects!$A$2:$A$101,0))="","",INDEX(Projects!$AG$2:$AG$101,MATCH($A15,Projects!$A$2:$A$101,0))),"")) | M15: =IF($A15="","",IFERROR(IF(INDEX(Projects!$AH$2:$AH$101,MATCH($A15,Projects!$A$2:$A$101,0))="","",INDEX(Projects!$AH$2:$AH$101,MATCH($A15,Projects!$A$2:$A$101,0))),"")) | N15: =IF($A15="","",IFERROR(IF(INDEX(Projects!$AI$2:$AI$101,MATCH($A15,Projects!$A$2:$A$101,0))="","",INDEX(Projects!$AI$2:$AI$101,MATCH($A15,Projects!$A$2:$A$101,0))),"")) | O15: =IF($A15="","",IFERROR(IF(INDEX(Projects!$AJ$2:$AJ$101,MATCH($A15,Projects!$A$2:$A$101,0))="","",INDEX(Projects!$AJ$2:$AJ$101,MATCH($A15,Projects!$A$2:$A$101,0))),""))
A16: =IF(INDEX(Projects!$A$2:$A$101,ROWS(A$9:A16))="","",INDEX(Projects!$A$2:$A$101,ROWS(A$9:A16))) | B16: =IF($A16="","",IFERROR(IF(INDEX(Projects!$D$2:$D$101,MATCH($A16,Projects!$A$2:$A$101,0))="","",INDEX(Projects!$D$2:$D$101,MATCH($A16,Projects!$A$2:$A$101,0))),"")) | C16: =IF($A16="","",IFERROR(IF(INDEX(Projects!$F$2:$F$101,MATCH($A16,Projects!$A$2:$A$101,0))="","",INDEX(Projects!$F$2:$F$101,MATCH($A16,Projects!$A$2:$A$101,0))),"")) | D16: =IF($A16="","",IFERROR(IF(INDEX(Projects!$W$2:$W$101,MATCH($A16,Projects!$A$2:$A$101,0))="","",INDEX(Projects!$W$2:$W$101,MATCH($A16,Projects!$A$2:$A$101,0))),"")) | E16: =IF($A16="","",IFERROR(IF(INDEX(Projects!$R$2:$R$101,MATCH($A16,Projects!$A$2:$A$101,0))="","",INDEX(Projects!$R$2:$R$101,MATCH($A16,Projects!$A$2:$A$101,0))),"")) | F16: =IF($A16="","",IFERROR(IF(INDEX(Projects!$T$2:$T$101,MATCH($A16,Projects!$A$2:$A$101,0))="","",INDEX(Projects!$T$2:$T$101,MATCH($A16,Projects!$A$2:$A$101,0))),"")) | G16: =IF($A16="","",IFERROR(IF(INDEX(Projects!$U$2:$U$101,MATCH($A16,Projects!$A$2:$A$101,0))="","",INDEX(Projects!$U$2:$U$101,MATCH($A16,Projects!$A$2:$A$101,0))),"")) | H16: =IF($A16="","",IFERROR(IF(INDEX(Projects!$Z$2:$Z$101,MATCH($A16,Projects!$A$2:$A$101,0))="","",INDEX(Projects!$Z$2:$Z$101,MATCH($A16,Projects!$A$2:$A$101,0))),"")) | I16: =IF($A16="","",IFERROR(IF(INDEX(Projects!$AB$2:$AB$101,MATCH($A16,Projects!$A$2:$A$101,0))="","",INDEX(Projects!$AB$2:$AB$101,MATCH($A16,Projects!$A$2:$A$101,0))),"")) | J16: =IF($A16="","",IFERROR(IF(INDEX(Projects!$AE$2:$AE$101,MATCH($A16,Projects!$A$2:$A$101,0))="","",INDEX(Projects!$AE$2:$AE$101,MATCH($A16,Projects!$A$2:$A$101,0))),"")) | K16: =IF($A16="","",IFERROR(IF(INDEX(Projects!$AF$2:$AF$101,MATCH($A16,Projects!$A$2:$A$101,0))="","",INDEX(Projects!$AF$2:$AF$101,MATCH($A16,Projects!$A$2:$A$101,0))),"")) | L16: =IF($A16="","",IFERROR(IF(INDEX(Projects!$AG$2:$AG$101,MATCH($A16,Projects!$A$2:$A$101,0))="","",INDEX(Projects!$AG$2:$AG$101,MATCH($A16,Projects!$A$2:$A$101,0))),"")) | M16: =IF($A16="","",IFERROR(IF(INDEX(Projects!$AH$2:$AH$101,MATCH($A16,Projects!$A$2:$A$101,0))="","",INDEX(Projects!$AH$2:$AH$101,MATCH($A16,Projects!$A$2:$A$101,0))),"")) | N16: =IF($A16="","",IFERROR(IF(INDEX(Projects!$AI$2:$AI$101,MATCH($A16,Projects!$A$2:$A$101,0))="","",INDEX(Projects!$AI$2:$AI$101,MATCH($A16,Projects!$A$2:$A$101,0))),"")) | O16: =IF($A16="","",IFERROR(IF(INDEX(Projects!$AJ$2:$AJ$101,MATCH($A16,Projects!$A$2:$A$101,0))="","",INDEX(Projects!$AJ$2:$AJ$101,MATCH($A16,Projects!$A$2:$A$101,0))),""))
A17: =IF(INDEX(Projects!$A$2:$A$101,ROWS(A$9:A17))="","",INDEX(Projects!$A$2:$A$101,ROWS(A$9:A17))) | B17: =IF($A17="","",IFERROR(IF(INDEX(Projects!$D$2:$D$101,MATCH($A17,Projects!$A$2:$A$101,0))="","",INDEX(Projects!$D$2:$D$101,MATCH($A17,Projects!$A$2:$A$101,0))),"")) | C17: =IF($A17="","",IFERROR(IF(INDEX(Projects!$F$2:$F$101,MATCH($A17,Projects!$A$2:$A$101,0))="","",INDEX(Projects!$F$2:$F$101,MATCH($A17,Projects!$A$2:$A$101,0))),"")) | D17: =IF($A17="","",IFERROR(IF(INDEX(Projects!$W$2:$W$101,MATCH($A17,Projects!$A$2:$A$101,0))="","",INDEX(Projects!$W$2:$W$101,MATCH($A17,Projects!$A$2:$A$101,0))),"")) | E17: =IF($A17="","",IFERROR(IF(INDEX(Projects!$R$2:$R$101,MATCH($A17,Projects!$A$2:$A$101,0))="","",INDEX(Projects!$R$2:$R$101,MATCH($A17,Projects!$A$2:$A$101,0))),"")) | F17: =IF($A17="","",IFERROR(IF(INDEX(Projects!$T$2:$T$101,MATCH($A17,Projects!$A$2:$A$101,0))="","",INDEX(Projects!$T$2:$T$101,MATCH($A17,Projects!$A$2:$A$101,0))),"")) | G17: =IF($A17="","",IFERROR(IF(INDEX(Projects!$U$2:$U$101,MATCH($A17,Projects!$A$2:$A$101,0))="","",INDEX(Projects!$U$2:$U$101,MATCH($A17,Projects!$A$2:$A$101,0))),"")) | H17: =IF($A17="","",IFERROR(IF(INDEX(Projects!$Z$2:$Z$101,MATCH($A17,Projects!$A$2:$A$101,0))="","",INDEX(Projects!$Z$2:$Z$101,MATCH($A17,Projects!$A$2:$A$101,0))),"")) | I17: =IF($A17="","",IFERROR(IF(INDEX(Projects!$AB$2:$AB$101,MATCH($A17,Projects!$A$2:$A$101,0))="","",INDEX(Projects!$AB$2:$AB$101,MATCH($A17,Projects!$A$2:$A$101,0))),"")) | J17: =IF($A17="","",IFERROR(IF(INDEX(Projects!$AE$2:$AE$101,MATCH($A17,Projects!$A$2:$A$101,0))="","",INDEX(Projects!$AE$2:$AE$101,MATCH($A17,Projects!$A$2:$A$101,0))),"")) | K17: =IF($A17="","",IFERROR(IF(INDEX(Projects!$AF$2:$AF$101,MATCH($A17,Projects!$A$2:$A$101,0))="","",INDEX(Projects!$AF$2:$AF$101,MATCH($A17,Projects!$A$2:$A$101,0))),"")) | L17: =IF($A17="","",IFERROR(IF(INDEX(Projects!$AG$2:$AG$101,MATCH($A17,Projects!$A$2:$A$101,0))="","",INDEX(Projects!$AG$2:$AG$101,MATCH($A17,Projects!$A$2:$A$101,0))),"")) | M17: =IF($A17="","",IFERROR(IF(INDEX(Projects!$AH$2:$AH$101,MATCH($A17,Projects!$A$2:$A$101,0))="","",INDEX(Projects!$AH$2:$AH$101,MATCH($A17,Projects!$A$2:$A$101,0))),"")) | N17: =IF($A17="","",IFERROR(IF(INDEX(Projects!$AI$2:$AI$101,MATCH($A17,Projects!$A$2:$A$101,0))="","",INDEX(Projects!$AI$2:$AI$101,MATCH($A17,Projects!$A$2:$A$101,0))),"")) | O17: =IF($A17="","",IFERROR(IF(INDEX(Projects!$AJ$2:$AJ$101,MATCH($A17,Projects!$A$2:$A$101,0))="","",INDEX(Projects!$AJ$2:$AJ$101,MATCH($A17,Projects!$A$2:$A$101,0))),""))
A18: =IF(INDEX(Projects!$A$2:$A$101,ROWS(A$9:A18))="","",INDEX(Projects!$A$2:$A$101,ROWS(A$9:A18))) | B18: =IF($A18="","",IFERROR(IF(INDEX(Projects!$D$2:$D$101,MATCH($A18,Projects!$A$2:$A$101,0))="","",INDEX(Projects!$D$2:$D$101,MATCH($A18,Projects!$A$2:$A$101,0))),"")) | C18: =IF($A18="","",IFERROR(IF(INDEX(Projects!$F$2:$F$101,MATCH($A18,Projects!$A$2:$A$101,0))="","",INDEX(Projects!$F$2:$F$101,MATCH($A18,Projects!$A$2:$A$101,0))),"")) | D18: =IF($A18="","",IFERROR(IF(INDEX(Projects!$W$2:$W$101,MATCH($A18,Projects!$A$2:$A$101,0))="","",INDEX(Projects!$W$2:$W$101,MATCH($A18,Projects!$A$2:$A$101,0))),"")) | E18: =IF($A18="","",IFERROR(IF(INDEX(Projects!$R$2:$R$101,MATCH($A18,Projects!$A$2:$A$101,0))="","",INDEX(Projects!$R$2:$R$101,MATCH($A18,Projects!$A$2:$A$101,0))),"")) | F18: =IF($A18="","",IFERROR(IF(INDEX(Projects!$T$2:$T$101,MATCH($A18,Projects!$A$2:$A$101,0))="","",INDEX(Projects!$T$2:$T$101,MATCH($A18,Projects!$A$2:$A$101,0))),"")) | G18: =IF($A18="","",IFERROR(IF(INDEX(Projects!$U$2:$U$101,MATCH($A18,Projects!$A$2:$A$101,0))="","",INDEX(Projects!$U$2:$U$101,MATCH($A18,Projects!$A$2:$A$101,0))),"")) | H18: =IF($A18="","",IFERROR(IF(INDEX(Projects!$Z$2:$Z$101,MATCH($A18,Projects!$A$2:$A$101,0))="","",INDEX(Projects!$Z$2:$Z$101,MATCH($A18,Projects!$A$2:$A$101,0))),"")) | I18: =IF($A18="","",IFERROR(IF(INDEX(Projects!$AB$2:$AB$101,MATCH($A18,Projects!$A$2:$A$101,0))="","",INDEX(Projects!$AB$2:$AB$101,MATCH($A18,Projects!$A$2:$A$101,0))),"")) | J18: =IF($A18="","",IFERROR(IF(INDEX(Projects!$AE$2:$AE$101,MATCH($A18,Projects!$A$2:$A$101,0))="","",INDEX(Projects!$AE$2:$AE$101,MATCH($A18,Projects!$A$2:$A$101,0))),"")) | K18: =IF($A18="","",IFERROR(IF(INDEX(Projects!$AF$2:$AF$101,MATCH($A18,Projects!$A$2:$A$101,0))="","",INDEX(Projects!$AF$2:$AF$101,MATCH($A18,Projects!$A$2:$A$101,0))),"")) | L18: =IF($A18="","",IFERROR(IF(INDEX(Projects!$AG$2:$AG$101,MATCH($A18,Projects!$A$2:$A$101,0))="","",INDEX(Projects!$AG$2:$AG$101,MATCH($A18,Projects!$A$2:$A$101,0))),"")) | M18: =IF($A18="","",IFERROR(IF(INDEX(Projects!$AH$2:$AH$101,MATCH($A18,Projects!$A$2:$A$101,0))="","",INDEX(Projects!$AH$2:$AH$101,MATCH($A18,Projects!$A$2:$A$101,0))),"")) | N18: =IF($A18="","",IFERROR(IF(INDEX(Projects!$AI$2:$AI$101,MATCH($A18,Projects!$A$2:$A$101,0))="","",INDEX(Projects!$AI$2:$AI$101,MATCH($A18,Projects!$A$2:$A$101,0))),"")) | O18: =IF($A18="","",IFERROR(IF(INDEX(Projects!$AJ$2:$AJ$101,MATCH($A18,Projects!$A$2:$A$101,0))="","",INDEX(Projects!$AJ$2:$AJ$101,MATCH($A18,Projects!$A$2:$A$101,0))),""))
A19: =IF(INDEX(Projects!$A$2:$A$101,ROWS(A$9:A19))="","",INDEX(Projects!$A$2:$A$101,ROWS(A$9:A19))) | B19: =IF($A19="","",IFERROR(IF(INDEX(Projects!$D$2:$D$101,MATCH($A19,Projects!$A$2:$A$101,0))="","",INDEX(Projects!$D$2:$D$101,MATCH($A19,Projects!$A$2:$A$101,0))),"")) | C19: =IF($A19="","",IFERROR(IF(INDEX(Projects!$F$2:$F$101,MATCH($A19,Projects!$A$2:$A$101,0))="","",INDEX(Projects!$F$2:$F$101,MATCH($A19,Projects!$A$2:$A$101,0))),"")) | D19: =IF($A19="","",IFERROR(IF(INDEX(Projects!$W$2:$W$101,MATCH($A19,Projects!$A$2:$A$101,0))="","",INDEX(Projects!$W$2:$W$101,MATCH($A19,Projects!$A$2:$A$101,0))),"")) | E19: =IF($A19="","",IFERROR(IF(INDEX(Projects!$R$2:$R$101,MATCH($A19,Projects!$A$2:$A$101,0))="","",INDEX(Projects!$R$2:$R$101,MATCH($A19,Projects!$A$2:$A$101,0))),"")) | F19: =IF($A19="","",IFERROR(IF(INDEX(Projects!$T$2:$T$101,MATCH($A19,Projects!$A$2:$A$101,0))="","",INDEX(Projects!$T$2:$T$101,MATCH($A19,Projects!$A$2:$A$101,0))),"")) | G19: =IF($A19="","",IFERROR(IF(INDEX(Projects!$U$2:$U$101,MATCH($A19,Projects!$A$2:$A$101,0))="","",INDEX(Projects!$U$2:$U$101,MATCH($A19,Projects!$A$2:$A$101,0))),"")) | H19: =IF($A19="","",IFERROR(IF(INDEX(Projects!$Z$2:$Z$101,MATCH($A19,Projects!$A$2:$A$101,0))="","",INDEX(Projects!$Z$2:$Z$101,MATCH($A19,Projects!$A$2:$A$101,0))),"")) | I19: =IF($A19="","",IFERROR(IF(INDEX(Projects!$AB$2:$AB$101,MATCH($A19,Projects!$A$2:$A$101,0))="","",INDEX(Projects!$AB$2:$AB$101,MATCH($A19,Projects!$A$2:$A$101,0))),"")) | J19: =IF($A19="","",IFERROR(IF(INDEX(Projects!$AE$2:$AE$101,MATCH($A19,Projects!$A$2:$A$101,0))="","",INDEX(Projects!$AE$2:$AE$101,MATCH($A19,Projects!$A$2:$A$101,0))),"")) | K19: =IF($A19="","",IFERROR(IF(INDEX(Projects!$AF$2:$AF$101,MATCH($A19,Projects!$A$2:$A$101,0))="","",INDEX(Projects!$AF$2:$AF$101,MATCH($A19,Projects!$A$2:$A$101,0))),"")) | L19: =IF($A19="","",IFERROR(IF(INDEX(Projects!$AG$2:$AG$101,MATCH($A19,Projects!$A$2:$A$101,0))="","",INDEX(Projects!$AG$2:$AG$101,MATCH($A19,Projects!$A$2:$A$101,0))),"")) | M19: =IF($A19="","",IFERROR(IF(INDEX(Projects!$AH$2:$AH$101,MATCH($A19,Projects!$A$2:$A$101,0))="","",INDEX(Projects!$AH$2:$AH$101,MATCH($A19,Projects!$A$2:$A$101,0))),"")) | N19: =IF($A19="","",IFERROR(IF(INDEX(Projects!$AI$2:$AI$101,MATCH($A19,Projects!$A$2:$A$101,0))="","",INDEX(Projects!$AI$2:$AI$101,MATCH($A19,Projects!$A$2:$A$101,0))),"")) | O19: =IF($A19="","",IFERROR(IF(INDEX(Projects!$AJ$2:$AJ$101,MATCH($A19,Projects!$A$2:$A$101,0))="","",INDEX(Projects!$AJ$2:$AJ$101,MATCH($A19,Projects!$A$2:$A$101,0))),""))
A20: =IF(INDEX(Projects!$A$2:$A$101,ROWS(A$9:A20))="","",INDEX(Projects!$A$2:$A$101,ROWS(A$9:A20))) | B20: =IF($A20="","",IFERROR(IF(INDEX(Projects!$D$2:$D$101,MATCH($A20,Projects!$A$2:$A$101,0))="","",INDEX(Projects!$D$2:$D$101,MATCH($A20,Projects!$A$2:$A$101,0))),"")) | C20: =IF($A20="","",IFERROR(IF(INDEX(Projects!$F$2:$F$101,MATCH($A20,Projects!$A$2:$A$101,0))="","",INDEX(Projects!$F$2:$F$101,MATCH($A20,Projects!$A$2:$A$101,0))),"")) | D20: =IF($A20="","",IFERROR(IF(INDEX(Projects!$W$2:$W$101,MATCH($A20,Projects!$A$2:$A$101,0))="","",INDEX(Projects!$W$2:$W$101,MATCH($A20,Projects!$A$2:$A$101,0))),"")) | E20: =IF($A20="","",IFERROR(IF(INDEX(Projects!$R$2:$R$101,MATCH($A20,Projects!$A$2:$A$101,0))="","",INDEX(Projects!$R$2:$R$101,MATCH($A20,Projects!$A$2:$A$101,0))),"")) | F20: =IF($A20="","",IFERROR(IF(INDEX(Projects!$T$2:$T$101,MATCH($A20,Projects!$A$2:$A$101,0))="","",INDEX(Projects!$T$2:$T$101,MATCH($A20,Projects!$A$2:$A$101,0))),"")) | G20: =IF($A20="","",IFERROR(IF(INDEX(Projects!$U$2:$U$101,MATCH($A20,Projects!$A$2:$A$101,0))="","",INDEX(Projects!$U$2:$U$101,MATCH($A20,Projects!$A$2:$A$101,0))),"")) | H20: =IF($A20="","",IFERROR(IF(INDEX(Projects!$Z$2:$Z$101,MATCH($A20,Projects!$A$2:$A$101,0))="","",INDEX(Projects!$Z$2:$Z$101,MATCH($A20,Projects!$A$2:$A$101,0))),"")) | I20: =IF($A20="","",IFERROR(IF(INDEX(Projects!$AB$2:$AB$101,MATCH($A20,Projects!$A$2:$A$101,0))="","",INDEX(Projects!$AB$2:$AB$101,MATCH($A20,Projects!$A$2:$A$101,0))),"")) | J20: =IF($A20="","",IFERROR(IF(INDEX(Projects!$AE$2:$AE$101,MATCH($A20,Projects!$A$2:$A$101,0))="","",INDEX(Projects!$AE$2:$AE$101,MATCH($A20,Projects!$A$2:$A$101,0))),"")) | K20: =IF($A20="","",IFERROR(IF(INDEX(Projects!$AF$2:$AF$101,MATCH($A20,Projects!$A$2:$A$101,0))="","",INDEX(Projects!$AF$2:$AF$101,MATCH($A20,Projects!$A$2:$A$101,0))),"")) | L20: =IF($A20="","",IFERROR(IF(INDEX(Projects!$AG$2:$AG$101,MATCH($A20,Projects!$A$2:$A$101,0))="","",INDEX(Projects!$AG$2:$AG$101,MATCH($A20,Projects!$A$2:$A$101,0))),"")) | M20: =IF($A20="","",IFERROR(IF(INDEX(Projects!$AH$2:$AH$101,MATCH($A20,Projects!$A$2:$A$101,0))="","",INDEX(Projects!$AH$2:$AH$101,MATCH($A20,Projects!$A$2:$A$101,0))),"")) | N20: =IF($A20="","",IFERROR(IF(INDEX(Projects!$AI$2:$AI$101,MATCH($A20,Projects!$A$2:$A$101,0))="","",INDEX(Projects!$AI$2:$AI$101,MATCH($A20,Projects!$A$2:$A$101,0))),"")) | O20: =IF($A20="","",IFERROR(IF(INDEX(Projects!$AJ$2:$AJ$101,MATCH($A20,Projects!$A$2:$A$101,0))="","",INDEX(Projects!$AJ$2:$AJ$101,MATCH($A20,Projects!$A$2:$A$101,0))),""))
... A38: =IF(INDEX(Projects!$A$2:$A$101,ROWS(A$9:A38))="","",INDEX(Projects!$A$2:$A$101,ROWS(A$9:A38))) | B38: =IF($A38="","",IFERROR(IF(INDEX(Projects!$D$2:$D$101,MATCH($A38,Projects!$A$2:$A$101,0))="","",INDEX(Projects!$D$2:$D$101,MATCH($A38,Projects!$A$2:$A$101,0))),"")) | C38: =IF($A38="","",IFERROR(IF(INDEX(Projects!$F$2:$F$101,MATCH($A38,Projects!$A$2:$A$101,0))="","",INDEX(Projects!$F$2:$F$101,MATCH($A38,Projects!$A$2:$A$101,0))),"")) | D38: =IF($A38="","",IFERROR(IF(INDEX(Projects!$W$2:$W$101,MATCH($A38,Projects!$A$2:$A$101,0))="","",INDEX(Projects!$W$2:$W$101,MATCH($A38,Projects!$A$2:$A$101,0))),"")) | E38: =IF($A38="","",IFERROR(IF(INDEX(Projects!$R$2:$R$101,MATCH($A38,Projects!$A$2:$A$101,0))="","",INDEX(Projects!$R$2:$R$101,MATCH($A38,Projects!$A$2:$A$101,0))),"")) | F38: =IF($A38="","",IFERROR(IF(INDEX(Projects!$T$2:$T$101,MATCH($A38,Projects!$A$2:$A$101,0))="","",INDEX(Projects!$T$2:$T$101,MATCH($A38,Projects!$A$2:$A$101,0))),"")) | G38: =IF($A38="","",IFERROR(IF(INDEX(Projects!$U$2:$U$101,MATCH($A38,Projects!$A$2:$A$101,0))="","",INDEX(Projects!$U$2:$U$101,MATCH($A38,Projects!$A$2:$A$101,0))),"")) | H38: =IF($A38="","",IFERROR(IF(INDEX(Projects!$Z$2:$Z$101,MATCH($A38,Projects!$A$2:$A$101,0))="","",INDEX(Projects!$Z$2:$Z$101,MATCH($A38,Projects!$A$2:$A$101,0))),"")) | I38: =IF($A38="","",IFERROR(IF(INDEX(Projects!$AB$2:$AB$101,MATCH($A38,Projects!$A$2:$A$101,0))="","",INDEX(Projects!$AB$2:$AB$101,MATCH($A38,Projects!$A$2:$A$101,0))),"")) | J38: =IF($A38="","",IFERROR(IF(INDEX(Projects!$AE$2:$AE$101,MATCH($A38,Projects!$A$2:$A$101,0))="","",INDEX(Projects!$AE$2:$AE$101,MATCH($A38,Projects!$A$2:$A$101,0))),"")) | K38: =IF($A38="","",IFERROR(IF(INDEX(Projects!$AF$2:$AF$101,MATCH($A38,Projects!$A$2:$A$101,0))="","",INDEX(Projects!$AF$2:$AF$101,MATCH($A38,Projects!$A$2:$A$101,0))),"")) | L38: =IF($A38="","",IFERROR(IF(INDEX(Projects!$AG$2:$AG$101,MATCH($A38,Projects!$A$2:$A$101,0))="","",INDEX(Projects!$AG$2:$AG$101,MATCH($A38,Projects!$A$2:$A$101,0))),"")) | M38: =IF($A38="","",IFERROR(IF(INDEX(Projects!$AH$2:$AH$101,MATCH($A38,Projects!$A$2:$A$101,0))="","",INDEX(Projects!$AH$2:$AH$101,MATCH($A38,Projects!$A$2:$A$101,0))),"")) | N38: =IF($A38="","",IFERROR(IF(INDEX(Projects!$AI$2:$AI$101,MATCH($A38,Projects!$A$2:$A$101,0))="","",INDEX(Projects!$AI$2:$AI$101,MATCH($A38,Projects!$A$2:$A$101,0))),"")) | O38: =IF($A38="","",IFERROR(IF(INDEX(Projects!$AJ$2:$AJ$101,MATCH($A38,Projects!$A$2:$A$101,0))="","",INDEX(Projects!$AJ$2:$AJ$101,MATCH($A38,Projects!$A$2:$A$101,0))),""))
A41: Alerts | E41: Today & Upcoming
A42: Alert | B42: Count | E42: Due | F42: Tasks | G42: Actions | H42: Total
A43: Projects past target completion | B43: =COUNTIF(Projects!$X$2:$X$101,"Overdue") -> 0 | E43: Overdue | F43: =COUNTIF(Tasks!$H$2:$H$1001,E43) -> 0 | G43: =COUNTIF(Actions!$M$2:$M$501,E43) -> 0 | H43: =F43+G43 -> 0
A44: Projects with Red overall health | B44: =COUNTIF(Projects!$AF$2:$AF$101,"Red") -> 0 | E44: Due Today | F44: =COUNTIF(Tasks!$H$2:$H$1001,E44) -> 0 | G44: =COUNTIF(Actions!$M$2:$M$501,E44) -> 0 | H44: =F44+G44 -> 0
A45: Overdue tasks | B45: =COUNTIF(Tasks!$H$2:$H$1001,"Overdue") -> 0 | E45: Due This Week | F45: =COUNTIF(Tasks!$H$2:$H$1001,E45) -> 0 | G45: =COUNTIF(Actions!$M$2:$M$501,E45) -> 0 | H45: =F45+G45 -> 0
A46: Overdue actions / decisions | B46: =COUNTIF(Actions!$M$2:$M$501,"Overdue") -> 0 | E46: Later | F46: =COUNTIF(Tasks!$H$2:$H$1001,E46) -> 0 | G46: =COUNTIF(Actions!$M$2:$M$501,E46) -> 0 | H46: =F46+G46 -> 0
A47: Overdue RFIs | B47: =COUNTIF(RFIs!$L$2:$L$501,"Overdue") -> 0 | E47: No Due Date | F47: =COUNTIF(Tasks!$H$2:$H$1001,E47) -> 0 | G47: =COUNTIF(Actions!$M$2:$M$501,E47) -> 0 | H47: =F47+G47 -> 0
A48: RFIs due within 7 days | B48: =COUNTIF(RFIs!$L$2:$L$501,"Due Soon") -> 0
A49: Overdue defects | B49: =COUNTIF(Defects!$M$2:$M$501,"Overdue") -> 0
A50: Overdue correspondence responses | B50: =COUNTIF(Correspondence!$L$2:$L$501,"Overdue") -> 0
A51: Overdue risk actions | B51: =COUNTIF(Risks!$R$2:$R$501,"Overdue") -> 0
A52: Overdue commissioning / handover items | B52: =COUNTIF(Checklist!$J$2:$J$501,"Overdue") -> 0
A53: Permits expired or expiring (60 days) | B53: =COUNTIF(Permits!$K$2:$K$501,"Expired")+COUNTIF(Permits!$K$2:$K$501,"Expiring Soon") -> 0
A54: Insurance / warranties expired or expiring | B54: =COUNTIF('Insurance Warranties'!$J$2:$J$501,"Expired")+COUNTIF('Insurance Warranties'!$J$2:$J$501,"Expiring Soon") -> 0
A55: Subcontractor insurance expired or expiring | B55: =COUNTIF(Subcontractors!$L$2:$L$501,"Expired")+COUNTIF(Subcontractors!$L$2:$L$501,"Expiring Soon") -> 0
A56: Training records expired or expiring | B56: =COUNTIF('Training Records'!$I$2:$I$501,"Expired")+COUNTIF('Training Records'!$I$2:$I$501,"Expiring Soon") -> 0
A57: Environmental exceedances | B57: =COUNTIF('Env Monitoring'!$K$2:$K$501,"Exceedance") -> 0
A58: Open High / Critical SQE issues | B58: =COUNTIFS('SQE Issues'!$C$2:$C$501,"High",'SQE Issues'!$H$2:$H$501,"<>Closed")+COUNTIFS('SQE Issues'!$C$2:$C$501,"Critical",'SQE Issues'!$H$2:$H$501,"<>Closed") -> 0
A59: Payment claims awaiting certification | B59: =COUNTIF('Payment Claims'!$G$2:$G$501,"Submitted") -> 0
A62: Upcoming tasks (next 15 open, soonest first) | F62: Upcoming actions & decisions (next 15 open)
A63: Task | B63: Project | C63: Due | D63: Bucket | F63: Action | G63: Project | H63: Owner | I63: Due | J63: Bucket
...

Sheet Project Summary
A1: Project Summary
A2: Pick a project in C3. Print this sheet (or use the PDF macro) as a one-page project report.
B3: Project:
B5: Overview | E5: Health
B6: Status | C6: =IFERROR(IF(INDEX(Projects!$D$2:$D$101,MATCH($C$3,Projects!$A$2:$A$101,0))="","",INDEX(Projects!$D$2:$D$101,MATCH($C$3,Projects!$A$2:$A$101,0))),"") | E6: Overall | F6: =IFERROR(IF(INDEX(Projects!$AF$2:$AF$101,MATCH($C$3,Projects!$A$2:$A$101,0))="","",INDEX(Projects!$AF$2:$AF$101,MATCH($C$3,Projects!$A$2:$A$101,0))),"")
B7: Project Manager | C7: =IFERROR(IF(INDEX(Projects!$F$2:$F$101,MATCH($C$3,Projects!$A$2:$A$101,0))="","",INDEX(Projects!$F$2:$F$101,MATCH($C$3,Projects!$A$2:$A$101,0))),"") | E7: Schedule | F7: =IFERROR(IF(INDEX(Projects!$Z$2:$Z$101,MATCH($C$3,Projects!$A$2:$A$101,0))="","",INDEX(Projects!$Z$2:$Z$101,MATCH($C$3,Projects!$A$2:$A$101,0))),"")
B8: Project Director | C8: =IFERROR(IF(INDEX(Projects!$G$2:$G$101,MATCH($C$3,Projects!$A$2:$A$101,0))="","",INDEX(Projects!$G$2:$G$101,MATCH($C$3,Projects!$A$2:$A$101,0))),"") | E8: Budget | F8: =IFERROR(IF(INDEX(Projects!$AB$2:$AB$101,MATCH($C$3,Projects!$A$2:$A$101,0))="","",INDEX(Projects!$AB$2:$AB$101,MATCH($C$3,Projects!$A$2:$A$101,0))),"")
B9: Project Sponsor | C9: =IFERROR(IF(INDEX(Projects!$H$2:$H$101,MATCH($C$3,Projects!$A$2:$A$101,0))="","",INDEX(Projects!$H$2:$H$101,MATCH($C$3,Projects!$A$2:$A$101,0))),"") | E9: Risk | F9: =IFERROR(IF(INDEX(Projects!$AE$2:$AE$101,MATCH($C$3,Projects!$A$2:$A$101,0))="","",INDEX(Projects!$AE$2:$AE$101,MATCH($C$3,Projects!$A$2:$A$101,0))),"")
B10: Location | C10: =IFERROR(IF(INDEX(Projects!$I$2:$I$101,MATCH($C$3,Projects!$A$2:$A$101,0))="","",INDEX(Projects!$I$2:$I$101,MATCH($C$3,Projects!$A$2:$A$101,0))),"") | E10: =IFERROR(IF(INDEX(Projects!$AK$2:$AK$101,MATCH($C$3,Projects!$A$2:$A$101,0))="","",INDEX(Projects!$AK$2:$AK$101,MATCH($C$3,Projects!$A$2:$A$101,0))),"")
B11: Contractor | C11: =IFERROR(IF(INDEX(Projects!$J$2:$J$101,MATCH($C$3,Projects!$A$2:$A$101,0))="","",INDEX(Projects!$J$2:$J$101,MATCH($C$3,Projects!$A$2:$A$101,0))),"")
B13: Budget | E13: Schedule
B14: Original Budget | C14: =IFERROR(IF(INDEX(Projects!$L$2:$L$101,MATCH($C$3,Projects!$A$2:$A$101,0))="","",INDEX(Projects!$L$2:$L$101,MATCH($C$3,Projects!$A$2:$A$101,0))),"") | E14: Start Date | F14: =IFERROR(IF(INDEX(Projects!$N$2:$N$101,MATCH($C$3,Projects!$A$2:$A$101,0))="","",INDEX(Projects!$N$2:$N$101,MATCH($C$3,Projects!$A$2:$A$101,0))),"")
B15: Latest Approved Budget | C15: =IFERROR(IF(INDEX(Projects!$M$2:$M$101,MATCH($C$3,Projects!$A$2:$A$101,0))="","",INDEX(Projects!$M$2:$M$101,MATCH($C$3,Projects!$A$2:$A$101,0))),"") | E15: Target Completion | F15: =IFERROR(IF(INDEX(Projects!$O$2:$O$101,MATCH($C$3,Projects!$A$2:$A$101,0))="","",INDEX(Projects!$O$2:$O$101,MATCH($C$3,Projects!$A$2:$A$101,0))),"")
B16: Approved Variations | C16: =IFERROR(IF(INDEX(Projects!$Q$2:$Q$101,MATCH($C$3,Projects!$A$2:$A$101,0))="","",INDEX(Projects!$Q$2:$Q$101,MATCH($C$3,Projects!$A$2:$A$101,0))),"") | E16: Approved EOT days | F16: =IFERROR(IF(INDEX(Projects!$V$2:$V$101,MATCH($C$3,Projects!$A$2:$A$101,0))="","",INDEX(Projects!$V$2:$V$101,MATCH($C$3,Projects!$A$2:$A$101,0))),"")
B17: Effective Budget | C17: =IFERROR(IF(INDEX(Projects!$R$2:$R$101,MATCH($C$3,Projects!$A$2:$A$101,0))="","",INDEX(Projects!$R$2:$R$101,MATCH($C$3,Projects!$A$2:$A$101,0))),"") | E17: Revised Completion | F17: =IFERROR(IF(INDEX(Projects!$W$2:$W$101,MATCH($C$3,Projects!$A$2:$A$101,0))="","",INDEX(Projects!$W$2:$W$101,MATCH($C$3,Projects!$A$2:$A$101,0))),"")
B18: Expenditure to Date | C18: =IFERROR(IF(INDEX(Projects!$S$2:$S$101,MATCH($C$3,Projects!$A$2:$A$101,0))="","",INDEX(Projects!$S$2:$S$101,MATCH($C$3,Projects!$A$2:$A$101,0))),"") | E18: Actual Completion | F18: =IFERROR(IF(INDEX(Projects!$P$2:$P$101,MATCH($C$3,Projects!$A$2:$A$101,0))="","",INDEX(Projects!$P$2:$P$101,MATCH($C$3,Projects!$A$2:$A$101,0))),"")
B19: Forecast at Completion | C19: =IFERROR(IF(INDEX(Projects!$T$2:$T$101,MATCH($C$3,Projects!$A$2:$A$101,0))="","",INDEX(Projects!$T$2:$T$101,MATCH($C$3,Projects!$A$2:$A$101,0))),"") | E19: Timeframe elapsed | F19: =IFERROR(IF(INDEX(Projects!$Y$2:$Y$101,MATCH($C$3,Projects!$A$2:$A$101,0))="","",INDEX(Projects!$Y$2:$Y$101,MATCH($C$3,Projects!$A$2:$A$101,0))),"")
B20: Variance (budget - forecast) | C20: =IFERROR(IF(INDEX(Projects!$U$2:$U$101,MATCH($C$3,Projects!$A$2:$A$101,0))="","",INDEX(Projects!$U$2:$U$101,MATCH($C$3,Projects!$A$2:$A$101,0))),"")
B21: Forecast % of budget | C21: =IFERROR(IF(INDEX(Projects!$AA$2:$AA$101,MATCH($C$3,Projects!$A$2:$A$101,0))="","",INDEX(Projects!$AA$2:$AA$101,MATCH($C$3,Projects!$A$2:$A$101,0))),"") | E21: Open items
E22: Open tasks | F22: =IFERROR(IF(INDEX(Projects!$AG$2:$AG$101,MATCH($C$3,Projects!$A$2:$A$101,0))="","",INDEX(Projects!$AG$2:$AG$101,MATCH($C$3,Projects!$A$2:$A$101,0))),"")
E23: Open actions | F23: =IFERROR(IF(INDEX(Projects!$AH$2:$AH$101,MATCH($C$3,Projects!$A$2:$A$101,0))="","",INDEX(Projects!$AH$2:$AH$101,MATCH($C$3,Projects!$A$2:$A$101,0))),"")
E24: Open RFIs | F24: =IFERROR(IF(INDEX(Projects!$AI$2:$AI$101,MATCH($C$3,Projects!$A$2:$A$101,0))="","",INDEX(Projects!$AI$2:$AI$101,MATCH($C$3,Projects!$A$2:$A$101,0))),"")
E25: Open defects | F25: =IFERROR(IF(INDEX(Projects!$AJ$2:$AJ$101,MATCH($C$3,Projects!$A$2:$A$101,0))="","",INDEX(Projects!$AJ$2:$AJ$101,MATCH($C$3,Projects!$A$2:$A$101,0))),"")
B27: Milestones
B28: Activity | C28: WBS | D28: % Complete | E28: Original | F28: Forecast | G28: Slip (days)
B29: =IFERROR(IF(INDEX(Milestones!$C$2:$C$501,MATCH(ROWS(B$29:B29),Milestones!$K$2:$K$501,0))="","",INDEX(Milestones!$C$2:$C$501,MATCH(ROWS(B$29:B29),Milestones!$K$2:$K$501,0))),"") | C29: =IFERROR(IF(INDEX(Milestones!$B$2:$B$501,MATCH(ROWS(B$29:B29),Milestones!$K$2:$K$501,0))="","",INDEX(Milestones!$B$2:$B$501,MATCH(ROWS(B$29:B29),Milestones!$K$2:$K$501,0))),"") | D29: =IFERROR(IF(INDEX(Milestones!$D$2:$D$501,MATCH(ROWS(B$29:B29),Milestones!$K$2:$K$501,0))="","",INDEX(Milestones!$D$2:$D$501,MATCH(ROWS(B$29:B29),Milestones!$K$2:$K$501,0))),"") | E29: =IFERROR(IF(INDEX(Milestones!$F$2:$F$501,MATCH(ROWS(B$29:B29),Milestones!$K$2:$K$501,0))="","",INDEX(Milestones!$F$2:$F$501,MATCH(ROWS(B$29:B29),Milestones!$K$2:$K$501,0))),"") | F29: =IFERROR(IF(INDEX(Milestones!$G$2:$G$501,MATCH(ROWS(B$29:B29),Milestones!$K$2:$K$501,0))="","",INDEX(Milestones!$G$2:$G$501,MATCH(ROWS(B$29:B29),Milestones!$K$2:$K$501,0))),"") | G29: =IFERROR(IF(INDEX(Milestones!$J$2:$J$501,MATCH(ROWS(B$29:B29),Milestones!$K$2:$K$501,0))="","",INDEX(Milestones!$J$2:$J$501,MATCH(ROWS(B$29:B29),Milestones!$K$2:$K$501,0))),"")
B30: =IFERROR(IF(INDEX(Milestones!$C$2:$C$501,MATCH(ROWS(B$29:B30),Milestones!$K$2:$K$501,0))="","",INDEX(Milestones!$C$2:$C$501,MATCH(ROWS(B$29:B30),Milestones!$K$2:$K$501,0))),"") | C30: =IFERROR(IF(INDEX(Milestones!$B$2:$B$501,MATCH(ROWS(B$29:B30),Milestones!$K$2:$K$501,0))="","",INDEX(Milestones!$B$2:$B$501,MATCH(ROWS(B$29:B30),Milestones!$K$2:$K$501,0))),"") | D30: =IFERROR(IF(INDEX(Milestones!$D$2:$D$501,MATCH(ROWS(B$29:B30),Milestones!$K$2:$K$501,0))="","",INDEX(Milestones!$D$2:$D$501,MATCH(ROWS(B$29:B30),Milestones!$K$2:$K$501,0))),"") | E30: =IFERROR(IF(INDEX(Milestones!$F$2:$F$501,MATCH(ROWS(B$29:B30),Milestones!$K$2:$K$501,0))="","",INDEX(Milestones!$F$2:$F$501,MATCH(ROWS(B$29:B30),Milestones!$K$2:$K$501,0))),"") | F30: =IFERROR(IF(INDEX(Milestones!$G$2:$G$501,MATCH(ROWS(B$29:B30),Milestones!$K$2:$K$501,0))="","",INDEX(Milestones!$G$2:$G$501,MATCH(ROWS(B$29:B30),Milestones!$K$2:$K$501,0))),"") | G30: =IFERROR(IF(INDEX(Milestones!$J$2:$J$501,MATCH(ROWS(B$29:B30),Milestones!$K$2:$K$501,0))="","",INDEX(Milestones!$J$2:$J$501,MATCH(ROWS(B$29:B30),Milestones!$K$2:$K$501,0))),"")
B31: =IFERROR(IF(INDEX(Milestones!$C$2:$C$501,MATCH(ROWS(B$29:B31),Milestones!$K$2:$K$501,0))="","",INDEX(Milestones!$C$2:$C$501,MATCH(ROWS(B$29:B31),Milestones!$K$2:$K$501,0))),"") | C31: =IFERROR(IF(INDEX(Milestones!$B$2:$B$501,MATCH(ROWS(B$29:B31),Milestones!$K$2:$K$501,0))="","",INDEX(Milestones!$B$2:$B$501,MATCH(ROWS(B$29:B31),Milestones!$K$2:$K$501,0))),"") | D31: =IFERROR(IF(INDEX(Milestones!$D$2:$D$501,MATCH(ROWS(B$29:B31),Milestones!$K$2:$K$501,0))="","",INDEX(Milestones!$D$2:$D$501,MATCH(ROWS(B$29:B31),Milestones!$K$2:$K$501,0))),"") | E31: =IFERROR(IF(INDEX(Milestones!$F$2:$F$501,MATCH(ROWS(B$29:B31),Milestones!$K$2:$K$501,0))="","",INDEX(Milestones!$F$2:$F$501,MATCH(ROWS(B$29:B31),Milestones!$K$2:$K$501,0))),"") | F31: =IFERROR(IF(INDEX(Milestones!$G$2:$G$501,MATCH(ROWS(B$29:B31),Milestones!$K$2:$K$501,0))="","",INDEX(Milestones!$G$2:$G$501,MATCH(ROWS(B$29:B31),Milestones!$K$2:$K$501,0))),"") | G31: =IFERROR(IF(INDEX(Milestones!$J$2:$J$501,MATCH(ROWS(B$29:B31),Milestones!$K$2:$K$501,0))="","",INDEX(Milestones!$J$2:$J$501,MATCH(ROWS(B$29:B31),Milestones!$K$2:$K$501,0))),"")
B32: =IFERROR(IF(INDEX(Milestones!$C$2:$C$501,MATCH(ROWS(B$29:B32),Milestones!$K$2:$K$501,0))="","",INDEX(Milestones!$C$2:$C$501,MATCH(ROWS(B$29:B32),Milestones!$K$2:$K$501,0))),"") | C32: =IFERROR(IF(INDEX(Milestones!$B$2:$B$501,MATCH(ROWS(B$29:B32),Milestones!$K$2:$K$501,0))="","",INDEX(Milestones!$B$2:$B$501,MATCH(ROWS(B$29:B32),Milestones!$K$2:$K$501,0))),"") | D32: =IFERROR(IF(INDEX(Milestones!$D$2:$D$501,MATCH(ROWS(B$29:B32),Milestones!$K$2:$K$501,0))="","",INDEX(Milestones!$D$2:$D$501,MATCH(ROWS(B$29:B32),Milestones!$K$2:$K$501,0))),"") | E32: =IFERROR(IF(INDEX(Milestones!$F$2:$F$501,MATCH(ROWS(B$29:B32),Milestones!$K$2:$K$501,0))="","",INDEX(Milestones!$F$2:$F$501,MATCH(ROWS(B$29:B32),Milestones!$K$2:$K$501,0))),"") | F32: =IFERROR(IF(INDEX(Milestones!$G$2:$G$501,MATCH(ROWS(B$29:B32),Milestones!$K$2:$K$501,0))="","",INDEX(Milestones!$G$2:$G$501,MATCH(ROWS(B$29:B32),Milestones!$K$2:$K$501,0))),"") | G32: =IFERROR(IF(INDEX(Milestones!$J$2:$J$501,MATCH(ROWS(B$29:B32),Milestones!$K$2:$K$501,0))="","",INDEX(Milestones!$J$2:$J$501,MATCH(ROWS(B$29:B32),Milestones!$K$2:$K$501,0))),"")
B33: =IFERROR(IF(INDEX(Milestones!$C$2:$C$501,MATCH(ROWS(B$29:B33),Milestones!$K$2:$K$501,0))="","",INDEX(Milestones!$C$2:$C$501,MATCH(ROWS(B$29:B33),Milestones!$K$2:$K$501,0))),"") | C33: =IFERROR(IF(INDEX(Milestones!$B$2:$B$501,MATCH(ROWS(B$29:B33),Milestones!$K$2:$K$501,0))="","",INDEX(Milestones!$B$2:$B$501,MATCH(ROWS(B$29:B33),Milestones!$K$2:$K$501,0))),"") | D33: =IFERROR(IF(INDEX(Milestones!$D$2:$D$501,MATCH(ROWS(B$29:B33),Milestones!$K$2:$K$501,0))="","",INDEX(Milestones!$D$2:$D$501,MATCH(ROWS(B$29:B33),Milestones!$K$2:$K$501,0))),"") | E33: =IFERROR(IF(INDEX(Milestones!$F$2:$F$501,MATCH(ROWS(B$29:B33),Milestones!$K$2:$K$501,0))="","",INDEX(Milestones!$F$2:$F$501,MATCH(ROWS(B$29:B33),Milestones!$K$2:$K$501,0))),"") | F33: =IFERROR(IF(INDEX(Milestones!$G$2:$G$501,MATCH(ROWS(B$29:B33),Milestones!$K$2:$K$501,0))="","",INDEX(Milestones!$G$2:$G$501,MATCH(ROWS(B$29:B33),Milestones!$K$2:$K$501,0))),"") | G33: =IFERROR(IF(INDEX(Milestones!$J$2:$J$501,MATCH(ROWS(B$29:B33),Milestones!$K$2:$K$501,0))="","",INDEX(Milestones!$J$2:$J$501,MATCH(ROWS(B$29:B33),Milestones!$K$2:$K$501,0))),"")
B34: =IFERROR(IF(INDEX(Milestones!$C$2:$C$501,MATCH(ROWS(B$29:B34),Milestones!$K$2:$K$501,0))="","",INDEX(Milestones!$C$2:$C$501,MATCH(ROWS(B$29:B34),Milestones!$K$2:$K$501,0))),"") | C34: =IFERROR(IF(INDEX(Milestones!$B$2:$B$501,MATCH(ROWS(B$29:B34),Milestones!$K$2:$K$501,0))="","",INDEX(Milestones!$B$2:$B$501,MATCH(ROWS(B$29:B34),Milestones!$K$2:$K$501,0))),"") | D34: =IFERROR(IF(INDEX(Milestones!$D$2:$D$501,MATCH(ROWS(B$29:B34),Milestones!$K$2:$K$501,0))="","",INDEX(Milestones!$D$2:$D$501,MATCH(ROWS(B$29:B34),Milestones!$K$2:$K$501,0))),"") | E34: =IFERROR(IF(INDEX(Milestones!$F$2:$F$501,MATCH(ROWS(B$29:B34),Milestones!$K$2:$K$501,0))="","",INDEX(Milestones!$F$2:$F$501,MATCH(ROWS(B$29:B34),Milestones!$K$2:$K$501,0))),"") | F34: =IFERROR(IF(INDEX(Milestones!$G$2:$G$501,MATCH(ROWS(B$29:B34),Milestones!$K$2:$K$501,0))="","",INDEX(Milestones!$G$2:$G$501,MATCH(ROWS(B$29:B34),Milestones!$K$2:$K$501,0))),"") | G34: =IFERROR(IF(INDEX(Milestones!$J$2:$J$501,MATCH(ROWS(B$29:B34),Milestones!$K$2:$K$501,0))="","",INDEX(Milestones!$J$2:$J$501,MATCH(ROWS(B$29:B34),Milestones!$K$2:$K$501,0))),"")
B35: =IFERROR(IF(INDEX(Milestones!$C$2:$C$501,MATCH(ROWS(B$29:B35),Milestones!$K$2:$K$501,0))="","",INDEX(Milestones!$C$2:$C$501,MATCH(ROWS(B$29:B35),Milestones!$K$2:$K$501,0))),"") | C35: =IFERROR(IF(INDEX(Milestones!$B$2:$B$501,MATCH(ROWS(B$29:B35),Milestones!$K$2:$K$501,0))="","",INDEX(Milestones!$B$2:$B$501,MATCH(ROWS(B$29:B35),Milestones!$K$2:$K$501,0))),"") | D35: =IFERROR(IF(INDEX(Milestones!$D$2:$D$501,MATCH(ROWS(B$29:B35),Milestones!$K$2:$K$501,0))="","",INDEX(Milestones!$D$2:$D$501,MATCH(ROWS(B$29:B35),Milestones!$K$2:$K$501,0))),"") | E35: =IFERROR(IF(INDEX(Milestones!$F$2:$F$501,MATCH(ROWS(B$29:B35),Milestones!$K$2:$K$501,0))="","",INDEX(Milestones!$F$2:$F$501,MATCH(ROWS(B$29:B35),Milestones!$K$2:$K$501,0))),"") | F35: =IFERROR(IF(INDEX(Milestones!$G$2:$G$501,MATCH(ROWS(B$29:B35),Milestones!$K$2:$K$501,0))="","",INDEX(Milestones!$G$2:$G$501,MATCH(ROWS(B$29:B35),Milestones!$K$2:$K$501,0))),"") | G35: =IFERROR(IF(INDEX(Milestones!$J$2:$J$501,MATCH(ROWS(B$29:B35),Milestones!$K$2:$K$501,0))="","",INDEX(Milestones!$J$2:$J$501,MATCH(ROWS(B$29:B35),Milestones!$K$2:$K$501,0))),"")
B36: =IFERROR(IF(INDEX(Milestones!$C$2:$C$501,MATCH(ROWS(B$29:B36),Milestones!$K$2:$K$501,0))="","",INDEX(Milestones!$C$2:$C$501,MATCH(ROWS(B$29:B36),Milestones!$K$2:$K$501,0))),"") | C36: =IFERROR(IF(INDEX(Milestones!$B$2:$B$501,MATCH(ROWS(B$29:B36),Milestones!$K$2:$K$501,0))="","",INDEX(Milestones!$B$2:$B$501,MATCH(ROWS(B$29:B36),Milestones!$K$2:$K$501,0))),"") | D36: =IFERROR(IF(INDEX(Milestones!$D$2:$D$501,MATCH(ROWS(B$29:B36),Milestones!$K$2:$K$501,0))="","",INDEX(Milestones!$D$2:$D$501,MATCH(ROWS(B$29:B36),Milestones!$K$2:$K$501,0))),"") | E36: =IFERROR(IF(INDEX(Milestones!$F$2:$F$501,MATCH(ROWS(B$29:B36),Milestones!$K$2:$K$501,0))="","",INDEX(Milestones!$F$2:$F$501,MATCH(ROWS(B$29:B36),Milestones!$K$2:$K$501,0))),"") | F36: =IFERROR(IF(INDEX(Milestones!$G$2:$G$501,MATCH(ROWS(B$29:B36),Milestones!$K$2:$K$501,0))="","",INDEX(Milestones!$G$2:$G$501,MATCH(ROWS(B$29:B36),Milestones!$K$2:$K$501,0))),"") | G36: =IFERROR(IF(INDEX(Milestones!$J$2:$J$501,MATCH(ROWS(B$29:B36),Milestones!$K$2:$K$501,0))="","",INDEX(Milestones!$J$2:$J$501,MATCH(ROWS(B$29:B36),Milestones!$K$2:$K$501,0))),"")
B37: =IFERROR(IF(INDEX(Milestones!$C$2:$C$501,MATCH(ROWS(B$29:B37),Milestones!$K$2:$K$501,0))="","",INDEX(Milestones!$C$2:$C$501,MATCH(ROWS(B$29:B37),Milestones!$K$2:$K$501,0))),"") | C37: =IFERROR(IF(INDEX(Milestones!$B$2:$B$501,MATCH(ROWS(B$29:B37),Milestones!$K$2:$K$501,0))="","",INDEX(Milestones!$B$2:$B$501,MATCH(ROWS(B$29:B37),Milestones!$K$2:$K$501,0))),"") | D37: =IFERROR(IF(INDEX(Milestones!$D$2:$D$501,MATCH(ROWS(B$29:B37),Milestones!$K$2:$K$501,0))="","",INDEX(Milestones!$D$2:$D$501,MATCH(ROWS(B$29:B37),Milestones!$K$2:$K$501,0))),"") | E37: =IFERROR(IF(INDEX(Milestones!$F$2:$F$501,MATCH(ROWS(B$29:B37),Milestones!$K$2:$K$501,0))="","",INDEX(Milestones!$F$2:$F$501,MATCH(ROWS(B$29:B37),Milestones!$K$2:$K$501,0))),"") | F37: =IFERROR(IF(INDEX(Milestones!$G$2:$G$501,MATCH(ROWS(B$29:B37),Milestones!$K$2:$K$501,0))="","",INDEX(Milestones!$G$2:$G$501,MATCH(ROWS(B$29:B37),Milestones!$K$2:$K$501,0))),"") | G37: =IFERROR(IF(INDEX(Milestones!$J$2:$J$501,MATCH(ROWS(B$29:B37),Milestones!$K$2:$K$501,0))="","",INDEX(Milestones!$J$2:$J$501,MATCH(ROWS(B$29:B37),Milestones!$K$2:$K$501,0))),"")
B38: =IFERROR(IF(INDEX(Milestones!$C$2:$C$501,MATCH(ROWS(B$29:B38),Milestones!$K$2:$K$501,0))="","",INDEX(Milestones!$C$2:$C$501,MATCH(ROWS(B$29:B38),Milestones!$K$2:$K$501,0))),"") | C38: =IFERROR(IF(INDEX(Milestones!$B$2:$B$501,MATCH(ROWS(B$29:B38),Milestones!$K$2:$K$501,0))="","",INDEX(Milestones!$B$2:$B$501,MATCH(ROWS(B$29:B38),Milestones!$K$2:$K$501,0))),"") | D38: =IFERROR(IF(INDEX(Milestones!$D$2:$D$501,MATCH(ROWS(B$29:B38),Milestones!$K$2:$K$501,0))="","",INDEX(Milestones!$D$2:$D$501,MATCH(ROWS(B$29:B38),Milestones!$K$2:$K$501,0))),"") | E38: =IFERROR(IF(INDEX(Milestones!$F$2:$F$501,MATCH(ROWS(B$29:B38),Milestones!$K$2:$K$501,0))="","",INDEX(Milestones!$F$2:$F$501,MATCH(ROWS(B$29:B38),Milestones!$K$2:$K$501,0))),"") | F38: =IFERROR(IF(INDEX(Milestones!$G$2:$G$501,MATCH(ROWS(B$29:B38),Milestones!$K$2:$K$501,0))="","",INDEX(Milestones!$G$2:$G$501,MATCH(ROWS(B$29:B38),Milestones!$K$2:$K$501,0))),"") | G38: =IFERROR(IF(INDEX(Milestones!$J$2:$J$501,MATCH(ROWS(B$29:B38),Milestones!$K$2:$K$501,0))="","",INDEX(Milestones!$J$2:$J$501,MATCH(ROWS(B$29:B38),Milestones!$K$2:$K$501,0))),"")
B39: =IFERROR(IF(INDEX(Milestones!$C$2:$C$501,MATCH(ROWS(B$29:B39),Milestones!$K$2:$K$501,0))="","",INDEX(Milestones!$C$2:$C$501,MATCH(ROWS(B$29:B39),Milestones!$K$2:$K$501,0))),"") | C39: =IFERROR(IF(INDEX(Milestones!$B$2:$B$501,MATCH(ROWS(B$29:B39),Milestones!$K$2:$K$501,0))="","",INDEX(Milestones!$B$2:$B$501,MATCH(ROWS(B$29:B39),Milestones!$K$2:$K$501,0))),"") | D39: =IFERROR(IF(INDEX(Milestones!$D$2:$D$501,MATCH(ROWS(B$29:B39),Milestones!$K$2:$K$501,0))="","",INDEX(Milestones!$D$2:$D$501,MATCH(ROWS(B$29:B39),Milestones!$K$2:$K$501,0))),"") | E39: =IFERROR(IF(INDEX(Milestones!$F$2:$F$501,MATCH(ROWS(B$29:B39),Milestones!$K$2:$K$501,0))="","",INDEX(Milestones!$F$2:$F$501,MATCH(ROWS(B$29:B39),Milestones!$K$2:$K$501,0))),"") | F39: =IFERROR(IF(INDEX(Milestones!$G$2:$G$501,MATCH(ROWS(B$29:B39),Milestones!$K$2:$K$501,0))="","",INDEX(Milestones!$G$2:$G$501,MATCH(ROWS(B$29:B39),Milestones!$K$2:$K$501,0))),"") | G39: =IFERROR(IF(INDEX(Milestones!$J$2:$J$501,MATCH(ROWS(B$29:B39),Milestones!$K$2:$K$501,0))="","",INDEX(Milestones!$J$2:$J$501,MATCH(ROWS(B$29:B39),Milestones!$K$2:$K$501,0))),"")
B40: =IFERROR(IF(INDEX(Milestones!$C$2:$C$501,MATCH(ROWS(B$29:B40),Milestones!$K$2:$K$501,0))="","",INDEX(Milestones!$C$2:$C$501,MATCH(ROWS(B$29:B40),Milestones!$K$2:$K$501,0))),"") | C40: =IFERROR(IF(INDEX(Milestones!$B$2:$B$501,MATCH(ROWS(B$29:B40),Milestones!$K$2:$K$501,0))="","",INDEX(Milestones!$B$2:$B$501,MATCH(ROWS(B$29:B40),Milestones!$K$2:$K$501,0))),"") | D40: =IFERROR(IF(INDEX(Milestones!$D$2:$D$501,MATCH(ROWS(B$29:B40),Milestones!$K$2:$K$501,0))="","",INDEX(Milestones!$D$2:$D$501,MATCH(ROWS(B$29:B40),Milestones!$K$2:$K$501,0))),"") | E40: =IFERROR(IF(INDEX(Milestones!$F$2:$F$501,MATCH(ROWS(B$29:B40),Milestones!$K$2:$K$501,0))="","",INDEX(Milestones!$F$2:$F$501,MATCH(ROWS(B$29:B40),Milestones!$K$2:$K$501,0))),"") | F40: =IFERROR(IF(INDEX(Milestones!$G$2:$G$501,MATCH(ROWS(B$29:B40),Milestones!$K$2:$K$501,0))="","",INDEX(Milestones!$G$2:$G$501,MATCH(ROWS(B$29:B40),Milestones!$K$2:$K$501,0))),"") | G40: =IFERROR(IF(INDEX(Milestones!$J$2:$J$501,MATCH(ROWS(B$29:B40),Milestones!$K$2:$K$501,0))="","",INDEX(Milestones!$J$2:$J$501,MATCH(ROWS(B$29:B40),Milestones!$K$2:$K$501,0))),"")
B43: Top open risks
B44: Risk | C44: Band | D44: Owner | E44: Status | F44: Mitigation | G44: Due
